2022-01-07 10:32:34,582 -  nornir.core -     INFO -        run() - Running task 'netmiko_send_command' with args {'command_string': 'show ver', 'enable': False} on 3 hosts
2022-01-07 10:32:39,627 - nornir.core.task -    ERROR -      start() - Host '192.168.1.254': task 'netmiko_send_command' failed with traceback:
Traceback (most recent call last):
  File "C:\Users\re92619z\AppData\Local\Programs\Python\Python310\lib\site-packages\netmiko\base_connection.py", line 935, in establish_connection
    self.remote_conn_pre.connect(**ssh_connect_params)
  File "C:\Users\re92619z\AppData\Local\Programs\Python\Python310\lib\site-packages\paramiko\client.py", line 349, in connect
    retry_on_signal(lambda: sock.connect(addr))
  File "C:\Users\re92619z\AppData\Local\Programs\Python\Python310\lib\site-packages\paramiko\util.py", line 283, in retry_on_signal
    return function()
  File "C:\Users\re92619z\AppData\Local\Programs\Python\Python310\lib\site-packages\paramiko\client.py", line 349, in <lambda>
    retry_on_signal(lambda: sock.connect(addr))
TimeoutError: timed out

During handling of the above exception, another exception occurred:

Traceback (most recent call last):
  File "C:\Users\re92619z\AppData\Local\Programs\Python\Python310\lib\site-packages\nornir\core\task.py", line 99, in start
    r = self.task(self, **self.params)
  File "C:\Users\re92619z\AppData\Local\Programs\Python\Python310\lib\site-packages\nornir_netmiko\tasks\netmiko_send_command.py", line 26, in netmiko_send_command
    net_connect = task.host.get_connection(CONNECTION_NAME, task.nornir.config)
  File "C:\Users\re92619z\AppData\Local\Programs\Python\Python310\lib\site-packages\nornir\core\inventory.py", line 494, in get_connection
    self.open_connection(
  File "C:\Users\re92619z\AppData\Local\Programs\Python\Python310\lib\site-packages\nornir\core\inventory.py", line 546, in open_connection
    conn_obj.open(
  File "C:\Users\re92619z\AppData\Local\Programs\Python\Python310\lib\site-packages\nornir_netmiko\connections\netmiko.py", line 59, in open
    connection = ConnectHandler(**parameters)
  File "C:\Users\re92619z\AppData\Local\Programs\Python\Python310\lib\site-packages\netmiko\ssh_dispatcher.py", line 326, in ConnectHandler
    return ConnectionClass(*args, **kwargs)
  File "C:\Users\re92619z\AppData\Local\Programs\Python\Python310\lib\site-packages\netmiko\cisco\cisco_ios.py", line 17, in __init__
    return super().__init__(*args, **kwargs)
  File "C:\Users\re92619z\AppData\Local\Programs\Python\Python310\lib\site-packages\netmiko\base_connection.py", line 350, in __init__
    self._open()
  File "C:\Users\re92619z\AppData\Local\Programs\Python\Python310\lib\site-packages\netmiko\base_connection.py", line 355, in _open
    self.establish_connection()
  File "C:\Users\re92619z\AppData\Local\Programs\Python\Python310\lib\site-packages\netmiko\base_connection.py", line 957, in establish_connection
    raise NetmikoTimeoutException(msg)
netmiko.ssh_exception.NetmikoTimeoutException: TCP connection to device failed.

Common causes of this problem are:
1. Incorrect hostname or IP address.
2. Wrong TCP port.
3. Intermediate firewall blocking access.

Device settings: cisco_ios 192.168.1.254:22



2022-01-07 10:32:39,627 - nornir.core.task -    ERROR -      start() - Host '192.168.1.1': task 'netmiko_send_command' failed with traceback:
Traceback (most recent call last):
  File "C:\Users\re92619z\AppData\Local\Programs\Python\Python310\lib\site-packages\netmiko\base_connection.py", line 935, in establish_connection
    self.remote_conn_pre.connect(**ssh_connect_params)
  File "C:\Users\re92619z\AppData\Local\Programs\Python\Python310\lib\site-packages\paramiko\client.py", line 349, in connect
    retry_on_signal(lambda: sock.connect(addr))
  File "C:\Users\re92619z\AppData\Local\Programs\Python\Python310\lib\site-packages\paramiko\util.py", line 283, in retry_on_signal
    return function()
  File "C:\Users\re92619z\AppData\Local\Programs\Python\Python310\lib\site-packages\paramiko\client.py", line 349, in <lambda>
    retry_on_signal(lambda: sock.connect(addr))
TimeoutError: timed out

During handling of the above exception, another exception occurred:

Traceback (most recent call last):
  File "C:\Users\re92619z\AppData\Local\Programs\Python\Python310\lib\site-packages\nornir\core\task.py", line 99, in start
    r = self.task(self, **self.params)
  File "C:\Users\re92619z\AppData\Local\Programs\Python\Python310\lib\site-packages\nornir_netmiko\tasks\netmiko_send_command.py", line 26, in netmiko_send_command
    net_connect = task.host.get_connection(CONNECTION_NAME, task.nornir.config)
  File "C:\Users\re92619z\AppData\Local\Programs\Python\Python310\lib\site-packages\nornir\core\inventory.py", line 494, in get_connection
    self.open_connection(
  File "C:\Users\re92619z\AppData\Local\Programs\Python\Python310\lib\site-packages\nornir\core\inventory.py", line 546, in open_connection
    conn_obj.open(
  File "C:\Users\re92619z\AppData\Local\Programs\Python\Python310\lib\site-packages\nornir_netmiko\connections\netmiko.py", line 59, in open
    connection = ConnectHandler(**parameters)
  File "C:\Users\re92619z\AppData\Local\Programs\Python\Python310\lib\site-packages\netmiko\ssh_dispatcher.py", line 326, in ConnectHandler
    return ConnectionClass(*args, **kwargs)
  File "C:\Users\re92619z\AppData\Local\Programs\Python\Python310\lib\site-packages\netmiko\cisco\cisco_ios.py", line 17, in __init__
    return super().__init__(*args, **kwargs)
  File "C:\Users\re92619z\AppData\Local\Programs\Python\Python310\lib\site-packages\netmiko\base_connection.py", line 350, in __init__
    self._open()
  File "C:\Users\re92619z\AppData\Local\Programs\Python\Python310\lib\site-packages\netmiko\base_connection.py", line 355, in _open
    self.establish_connection()
  File "C:\Users\re92619z\AppData\Local\Programs\Python\Python310\lib\site-packages\netmiko\base_connection.py", line 957, in establish_connection
    raise NetmikoTimeoutException(msg)
netmiko.ssh_exception.NetmikoTimeoutException: TCP connection to device failed.

Common causes of this problem are:
1. Incorrect hostname or IP address.
2. Wrong TCP port.
3. Intermediate firewall blocking access.

Device settings: cisco_ios 192.168.1.1:22



2022-01-07 10:32:39,628 - nornir.core.task -    ERROR -      start() - Host '192.168.1.3': task 'netmiko_send_command' failed with traceback:
Traceback (most recent call last):
  File "C:\Users\re92619z\AppData\Local\Programs\Python\Python310\lib\site-packages\netmiko\base_connection.py", line 935, in establish_connection
    self.remote_conn_pre.connect(**ssh_connect_params)
  File "C:\Users\re92619z\AppData\Local\Programs\Python\Python310\lib\site-packages\paramiko\client.py", line 349, in connect
    retry_on_signal(lambda: sock.connect(addr))
  File "C:\Users\re92619z\AppData\Local\Programs\Python\Python310\lib\site-packages\paramiko\util.py", line 283, in retry_on_signal
    return function()
  File "C:\Users\re92619z\AppData\Local\Programs\Python\Python310\lib\site-packages\paramiko\client.py", line 349, in <lambda>
    retry_on_signal(lambda: sock.connect(addr))
TimeoutError: timed out

During handling of the above exception, another exception occurred:

Traceback (most recent call last):
  File "C:\Users\re92619z\AppData\Local\Programs\Python\Python310\lib\site-packages\nornir\core\task.py", line 99, in start
    r = self.task(self, **self.params)
  File "C:\Users\re92619z\AppData\Local\Programs\Python\Python310\lib\site-packages\nornir_netmiko\tasks\netmiko_send_command.py", line 26, in netmiko_send_command
    net_connect = task.host.get_connection(CONNECTION_NAME, task.nornir.config)
  File "C:\Users\re92619z\AppData\Local\Programs\Python\Python310\lib\site-packages\nornir\core\inventory.py", line 494, in get_connection
    self.open_connection(
  File "C:\Users\re92619z\AppData\Local\Programs\Python\Python310\lib\site-packages\nornir\core\inventory.py", line 546, in open_connection
    conn_obj.open(
  File "C:\Users\re92619z\AppData\Local\Programs\Python\Python310\lib\site-packages\nornir_netmiko\connections\netmiko.py", line 59, in open
    connection = ConnectHandler(**parameters)
  File "C:\Users\re92619z\AppData\Local\Programs\Python\Python310\lib\site-packages\netmiko\ssh_dispatcher.py", line 326, in ConnectHandler
    return ConnectionClass(*args, **kwargs)
  File "C:\Users\re92619z\AppData\Local\Programs\Python\Python310\lib\site-packages\netmiko\cisco\cisco_ios.py", line 17, in __init__
    return super().__init__(*args, **kwargs)
  File "C:\Users\re92619z\AppData\Local\Programs\Python\Python310\lib\site-packages\netmiko\base_connection.py", line 350, in __init__
    self._open()
  File "C:\Users\re92619z\AppData\Local\Programs\Python\Python310\lib\site-packages\netmiko\base_connection.py", line 355, in _open
    self.establish_connection()
  File "C:\Users\re92619z\AppData\Local\Programs\Python\Python310\lib\site-packages\netmiko\base_connection.py", line 957, in establish_connection
    raise NetmikoTimeoutException(msg)
netmiko.ssh_exception.NetmikoTimeoutException: TCP connection to device failed.

Common causes of this problem are:
1. Incorrect hostname or IP address.
2. Wrong TCP port.
3. Intermediate firewall blocking access.

Device settings: cisco_ios 192.168.1.3:22



2022-01-07 10:32:39,629 -  nornir.core -  WARNING -        run() - Task 'netmiko_send_command' has not been run – 0 hosts selected
2022-01-07 10:32:39,629 -  nornir.core -  WARNING -        run() - Task 'netmiko_send_command' has not been run – 0 hosts selected
2022-01-07 10:32:39,629 -  nornir.core -     INFO -        run() - Running task 'netmiko_send_command' with args {'command_string': 'show processes cpu | i five', 'enable': True} on 3 hosts
2022-01-07 10:32:39,630 -  nornir.core -     INFO -        run() - Running task 'netmiko_send_command' with args {'command_string': 'show runn | i hostname', 'enable': True} on 3 hosts
2022-01-07 10:32:39,630 -  nornir.core -  WARNING -        run() - Task 'netmiko_send_command' has not been run – 0 hosts selected
2022-01-07 10:32:39,630 -  nornir.core -  WARNING -        run() - Task 'netmiko_send_command' has not been run – 0 hosts selected
